<?xml version="1.0" encoding="utf-8"?>
<!-- This URDF was automatically created by SolidWorks to URDF Exporter! Originally created by Stephen Brawner (brawner@gmail.com) 
     Commit Version: 1.6.0-4-g7f85cfe  Build Version: 1.6.7995.38578
     For more information, please see http://wiki.ros.org/sw_urdf_exporter -->
<robot
  name="Active_Vision_Platform">
  <link
    name="base_link">
    <inertial>
      <origin
        xyz="0.317477964520347 -0.330969894003123 0.175977174132142"
        rpy="0 0 0" />
      <mass
        value="0.175" />
      <inertia
        ixx="0.000583456354562162"
        ixy="-7.14891953851568E-06"
        ixz="4.53483359986207E-05"
        iyy="0.000640864540576776"
        iyz="6.40389410938351E-05"
        izz="0.000161784736864578" />
    </inertial>
    <visual>
      <origin
        xyz="0 0 0"
        rpy="0 0 0" />
      <geometry>
        <mesh
          filename="./meshes/base_link.STL" />
      </geometry>
      <material
        name="">
        <color
          rgba="0.792156862745098 0.819607843137255 0.933333333333333 1" />
      </material>
    </visual>
    <collision>
      <origin
        xyz="0 0 0"
        rpy="0 0 0" />
      <geometry>
        <mesh
          filename="./meshes/base_link.STL" />
      </geometry>
    </collision>
  </link>
  <link
    name="Empty_Link1">
    <inertial>
      <origin
        xyz="0.317477964520347 -0.330969894003123 0.175977174132142"
        rpy="0 0 0" />
      <mass
        value="0.175" />
      <inertia
        ixx="0.000583456354562162"
        ixy="-7.14891953851568E-06"
        ixz="4.53483359986207E-05"
        iyy="0.000640864540576776"
        iyz="6.40389410938351E-05"
        izz="0.000161784736864578" />
    </inertial>
    <visual>
      <origin
        xyz="0 0 0"
        rpy="0 0 0" />
      <geometry>
        <mesh
          filename="./meshes/Empty_Link1.STL" />
      </geometry>
      <material
        name="">
        <color
          rgba="0.792156862745098 0.819607843137255 0.933333333333333 1" />
      </material>
    </visual>
    <collision>
      <origin
        xyz="0 0 0"
        rpy="0 0 0" />
      <geometry>
        <mesh
          filename="./meshes/Empty_Link1.STL" />
      </geometry>
    </collision>
  </link>
  <joint
    name="joint1"
    type="continuous">
    <origin
      xyz="0.31194 -0.10063 -0.3345"
      rpy="3.1351 0.967 -1.5786" />
    <parent
      link="base_link" />
    <child
      link="Empty_Link1" />
    <axis
      xyz="0 0 -1" />
  </joint>
  <link
    name="Empty_Link2">
    <inertial>
      <origin
        xyz="0.317477964520347 -0.330969894003123 0.175977174132142"
        rpy="0 0 0" />
      <mass
        value="0.175" />
      <inertia
        ixx="0.000583456354562162"
        ixy="-7.14891953851568E-06"
        ixz="4.53483359986207E-05"
        iyy="0.000640864540576776"
        iyz="6.40389410938351E-05"
        izz="0.000161784736864578" />
    </inertial>
    <visual>
      <origin
        xyz="0 0 0"
        rpy="0 0 0" />
      <geometry>
        <mesh
          filename="./meshes/Empty_Link2.STL" />
      </geometry>
      <material
        name="">
        <color
          rgba="0.792156862745098 0.819607843137255 0.933333333333333 1" />
      </material>
    </visual>
    <collision>
      <origin
        xyz="0 0 0"
        rpy="0 0 0" />
      <geometry>
        <mesh
          filename="./meshes/Empty_Link2.STL" />
      </geometry>
    </collision>
  </link>
  <joint
    name="joint2"
    type="continuous">
    <origin
      xyz="0.030254 -0.0087565 -0.070686"
      rpy="-1.5747 -0.5805 -3.1416" />
    <parent
      link="Empty_Link1" />
    <child
      link="Empty_Link2" />
    <axis
      xyz="0 0 -1" />
  </joint>
</robot>