<mujoco model="Active_Vision_Platform">
  <default>
    <default class="robot">
      <default class="motor">
        <joint />
        <motor />
      </default>
      <default class="visual">
        <geom material="visualgeom" contype="0" conaffinity="0" group="2" />
      </default>
      <default class="collision">
        <geom material="collision_material" condim="3" contype="0" conaffinity="1" priority="1" group="1" solref="0.005 1" solimp="0.99 0.999 1e-05" friction="1 0.01 0.01" />
      </default>
    </default>
  </default>

  <compiler angle="radian" />

  <asset>
    <material name="visualgeom" rgba="0.792156862745098 0.819607843137255 0.933333333333333 1" />
    <material name="default_material" rgba="0.7 0.7 0.7 1" />
    <material name="collision_material" rgba="1.0 0.28 0.1 0.9" />
    <mesh name="base_link.obj" file="./meshes/base_link.obj" />
    <mesh name="Empty_Link1.obj" file="./meshes/Empty_Link1.obj" />
    <mesh name="Empty_Link2.obj" file="./meshes/Empty_Link2.obj" />
  </asset>

  <worldbody>
    <body name="base_link" pos="0.00000000 0.00000000 0.33450000" childclass="robot">
      <inertial pos="0.317477964520347 -0.330969894003123 0.175977174132142" mass="0.175" diaginertia="0.000583456354562162 0.000640864540576776 0.000161784736864578" />
      <geom name="base_link_collision" type="mesh" mesh="base_link.obj" class="collision" />
      <geom name="base_link_visual" type="mesh" mesh="base_link.obj" material="visualgeom" class="visual" />
      <body name="Empty_Link1" pos="0.31194 -0.10063 -0.3345" quat="-0.32797432617233774 0.6246739242891658 -0.6274251550311 -0.32947382979407475">
        <joint name="joint1" type="hinge" class="motor" axis="0 0 -1" />
        <inertial pos="0.317477964520347 -0.330969894003123 0.175977174132142" mass="0.175" diaginertia="0.000583456354562162 0.000640864540576776 0.000161784736864578" />
        <geom name="Empty_Link1_collision" type="mesh" mesh="Empty_Link1.obj" class="collision" />
        <geom name="Empty_Link1_visual" type="mesh" mesh="Empty_Link1.obj" material="visualgeom" class="visual" />
        <body name="Empty_Link2" pos="0.030254 -0.0087565 -0.070686" quat="-0.20276523400275737 -0.20197027798886577 0.6788520501921232 -0.6762057088185948">
          <joint name="joint2" type="hinge" class="motor" axis="0 0 -1" />
          <inertial pos="0.317477964520347 -0.330969894003123 0.175977174132142" mass="0.175" diaginertia="0.000583456354562162 0.000640864540576776 0.000161784736864578" />
          <geom name="Empty_Link2_collision" type="mesh" mesh="Empty_Link2.obj" class="collision" />
          <geom name="Empty_Link2_visual" type="mesh" mesh="Empty_Link2.obj" material="visualgeom" class="visual" />
        </body>
      </body>
      <camera name="closeup" pos="0.15 0.15 0.25" quat="0.65 0.28 0.2 0.68" />
      <camera name="front" pos="0.0 0.35 0.15" quat="0.71 0.0 0.0 0.71" />
      <camera name="side" pos="-0.35 0.0 0.15" quat="0.5 -0.5 0.5 0.5" />
    </body>
  </worldbody>

  <actuator>
    <motor name="joint1_ctrl" joint="joint1" class="motor" />
    <motor name="joint2_ctrl" joint="joint2" class="motor" />
  </actuator>

  <contact>
    <exclude body1="base_link" body2="Empty_Link1" />
    <exclude body1="Empty_Link1" body2="Empty_Link2" />
  </contact>
</mujoco>